2021-01-26 23:01:51,780 django.utils.autoreload INFO     Watching for file changes with StatReloader
2021-01-26 23:02:11,226 sample.views DEBUG    tyler has logged in
2021-01-26 23:02:24,389 sample.views DEBUG    User has logged out
2021-01-29 02:53:30,683 django.utils.autoreload INFO     Watching for file changes with StatReloader
2021-01-29 02:53:52,089 django.utils.autoreload INFO     Watching for file changes with StatReloader
2021-01-29 02:53:52,254 asyncio      DEBUG    Using selector: EpollSelector
2021-01-29 02:54:05,968 django.request WARNING  Not Found: /favicon.ico
2021-01-29 02:54:42,815 sample.views DEBUG    creating account with name: Adrien
2021-01-29 02:54:49,842 sample.views DEBUG    Adrien has logged in
2021-01-29 02:56:02,629 django.request WARNING  Not Found: /profile.html
2021-01-29 02:56:22,105 django.request WARNING  Not Found: /blank.html
2021-01-29 02:56:40,719 asyncio      DEBUG    Using selector: EpollSelector
2021-01-29 03:00:13,060 django.utils.autoreload INFO     Watching for file changes with StatReloader
2021-01-29 03:00:47,560 django.request WARNING  Not Found: /index.html
2021-01-30 02:06:31,653 django.utils.autoreload INFO     Watching for file changes with StatReloader
2021-01-30 02:08:02,411 django.utils.autoreload INFO     /code/sample/views.py changed, reloading.
2021-01-30 02:08:02,412 asyncio      DEBUG    Using selector: EpollSelector
2021-01-30 02:08:02,779 django.utils.autoreload INFO     Watching for file changes with StatReloader
2021-02-02 16:17:24,041 django.utils.autoreload INFO     Watching for file changes with StatReloader
2021-02-02 16:19:32,994 asyncio      DEBUG    Using selector: EpollSelector
2021-02-02 16:25:13,375 django.utils.autoreload INFO     Watching for file changes with StatReloader
2021-02-02 16:26:59,999 asyncio      DEBUG    Using selector: EpollSelector
2021-02-02 16:28:54,096 django.utils.autoreload INFO     Watching for file changes with StatReloader
2021-02-02 16:32:23,894 asyncio      DEBUG    Using selector: EpollSelector
2021-02-02 16:33:52,636 django.utils.autoreload INFO     Watching for file changes with StatReloader
2021-02-02 16:35:42,241 asyncio      DEBUG    Using selector: EpollSelector
2021-02-02 16:36:50,296 django.utils.autoreload INFO     Watching for file changes with StatReloader
2021-02-02 16:39:31,382 asyncio      DEBUG    Using selector: EpollSelector
2021-02-02 16:55:04,654 django.utils.autoreload INFO     Watching for file changes with StatReloader
2021-02-02 16:56:08,072 django.request WARNING  Not Found: /favicon.ico
2021-02-02 16:57:03,289 django.request ERROR    Internal Server Error: /register
Traceback (most recent call last):
  File "/usr/local/lib/python3.9/site-packages/django/db/backends/utils.py", line 84, in _execute
    return self.cursor.execute(sql, params)
psycopg2.errors.UndefinedTable: relation "auth_user" does not exist
LINE 1: SELECT (1) AS "a" FROM "auth_user" WHERE "auth_user"."userna...
                               ^


The above exception was the direct cause of the following exception:

Traceback (most recent call last):
  File "/usr/local/lib/python3.9/site-packages/django/core/handlers/exception.py", line 47, in inner
    response = get_response(request)
  File "/usr/local/lib/python3.9/site-packages/django/core/handlers/base.py", line 181, in _get_response
    response = wrapped_callback(request, *callback_args, **callback_kwargs)
  File "/code/sample/decorators.py", line 9, in wrapper_func
    return view_func(request, *args, **kwargs)
  File "/code/sample/views.py", line 35, in register
    if form.is_valid():
  File "/usr/local/lib/python3.9/site-packages/django/forms/forms.py", line 177, in is_valid
    return self.is_bound and not self.errors
  File "/usr/local/lib/python3.9/site-packages/django/forms/forms.py", line 172, in errors
    self.full_clean()
  File "/usr/local/lib/python3.9/site-packages/django/forms/forms.py", line 376, in full_clean
    self._post_clean()
  File "/usr/local/lib/python3.9/site-packages/django/contrib/auth/forms.py", line 124, in _post_clean
    super()._post_clean()
  File "/usr/local/lib/python3.9/site-packages/django/forms/models.py", line 411, in _post_clean
    self.validate_unique()
  File "/usr/local/lib/python3.9/site-packages/django/forms/models.py", line 420, in validate_unique
    self.instance.validate_unique(exclude=exclude)
  File "/usr/local/lib/python3.9/site-packages/django/db/models/base.py", line 1009, in validate_unique
    errors = self._perform_unique_checks(unique_checks)
  File "/usr/local/lib/python3.9/site-packages/django/db/models/base.py", line 1112, in _perform_unique_checks
    if qs.exists():
  File "/usr/local/lib/python3.9/site-packages/django/db/models/query.py", line 809, in exists
    return self.query.has_results(using=self.db)
  File "/usr/local/lib/python3.9/site-packages/django/db/models/sql/query.py", line 535, in has_results
    return compiler.has_results()
  File "/usr/local/lib/python3.9/site-packages/django/db/models/sql/compiler.py", line 1126, in has_results
    return bool(self.execute_sql(SINGLE))
  File "/usr/local/lib/python3.9/site-packages/django/db/models/sql/compiler.py", line 1156, in execute_sql
    cursor.execute(sql, params)
  File "/usr/local/lib/python3.9/site-packages/django/db/backends/utils.py", line 98, in execute
    return super().execute(sql, params)
  File "/usr/local/lib/python3.9/site-packages/django/db/backends/utils.py", line 66, in execute
    return self._execute_with_wrappers(sql, params, many=False, executor=self._execute)
  File "/usr/local/lib/python3.9/site-packages/django/db/backends/utils.py", line 75, in _execute_with_wrappers
    return executor(sql, params, many, context)
  File "/usr/local/lib/python3.9/site-packages/django/db/backends/utils.py", line 84, in _execute
    return self.cursor.execute(sql, params)
  File "/usr/local/lib/python3.9/site-packages/django/db/utils.py", line 90, in __exit__
    raise dj_exc_value.with_traceback(traceback) from exc_value
  File "/usr/local/lib/python3.9/site-packages/django/db/backends/utils.py", line 84, in _execute
    return self.cursor.execute(sql, params)
django.db.utils.ProgrammingError: relation "auth_user" does not exist
LINE 1: SELECT (1) AS "a" FROM "auth_user" WHERE "auth_user"."userna...
                               ^

2021-02-02 16:57:30,480 django.request ERROR    Internal Server Error: /login
Traceback (most recent call last):
  File "/usr/local/lib/python3.9/site-packages/django/db/backends/utils.py", line 84, in _execute
    return self.cursor.execute(sql, params)
psycopg2.errors.UndefinedTable: relation "auth_user" does not exist
LINE 1: ...user"."is_active", "auth_user"."date_joined" FROM "auth_user...
                                                             ^


The above exception was the direct cause of the following exception:

Traceback (most recent call last):
  File "/usr/local/lib/python3.9/site-packages/django/core/handlers/exception.py", line 47, in inner
    response = get_response(request)
  File "/usr/local/lib/python3.9/site-packages/django/core/handlers/base.py", line 181, in _get_response
    response = wrapped_callback(request, *callback_args, **callback_kwargs)
  File "/code/sample/decorators.py", line 9, in wrapper_func
    return view_func(request, *args, **kwargs)
  File "/code/sample/views.py", line 51, in loginPage
    user = authenticate(request, username=username, password=password)
  File "/usr/local/lib/python3.9/site-packages/django/contrib/auth/__init__.py", line 73, in authenticate
    user = backend.authenticate(request, **credentials)
  File "/usr/local/lib/python3.9/site-packages/django/contrib/auth/backends.py", line 42, in authenticate
    user = UserModel._default_manager.get_by_natural_key(username)
  File "/usr/local/lib/python3.9/site-packages/django/contrib/auth/base_user.py", line 45, in get_by_natural_key
    return self.get(**{self.model.USERNAME_FIELD: username})
  File "/usr/local/lib/python3.9/site-packages/django/db/models/manager.py", line 85, in manager_method
    return getattr(self.get_queryset(), name)(*args, **kwargs)
  File "/usr/local/lib/python3.9/site-packages/django/db/models/query.py", line 425, in get
    num = len(clone)
  File "/usr/local/lib/python3.9/site-packages/django/db/models/query.py", line 269, in __len__
    self._fetch_all()
  File "/usr/local/lib/python3.9/site-packages/django/db/models/query.py", line 1308, in _fetch_all
    self._result_cache = list(self._iterable_class(self))
  File "/usr/local/lib/python3.9/site-packages/django/db/models/query.py", line 53, in __iter__
    results = compiler.execute_sql(chunked_fetch=self.chunked_fetch, chunk_size=self.chunk_size)
  File "/usr/local/lib/python3.9/site-packages/django/db/models/sql/compiler.py", line 1156, in execute_sql
    cursor.execute(sql, params)
  File "/usr/local/lib/python3.9/site-packages/django/db/backends/utils.py", line 98, in execute
    return super().execute(sql, params)
  File "/usr/local/lib/python3.9/site-packages/django/db/backends/utils.py", line 66, in execute
    return self._execute_with_wrappers(sql, params, many=False, executor=self._execute)
  File "/usr/local/lib/python3.9/site-packages/django/db/backends/utils.py", line 75, in _execute_with_wrappers
    return executor(sql, params, many, context)
  File "/usr/local/lib/python3.9/site-packages/django/db/backends/utils.py", line 84, in _execute
    return self.cursor.execute(sql, params)
  File "/usr/local/lib/python3.9/site-packages/django/db/utils.py", line 90, in __exit__
    raise dj_exc_value.with_traceback(traceback) from exc_value
  File "/usr/local/lib/python3.9/site-packages/django/db/backends/utils.py", line 84, in _execute
    return self.cursor.execute(sql, params)
django.db.utils.ProgrammingError: relation "auth_user" does not exist
LINE 1: ...user"."is_active", "auth_user"."date_joined" FROM "auth_user...
                                                             ^

2021-02-02 17:00:15,001 django.utils.autoreload INFO     /code/sample/views.py changed, reloading.
2021-02-02 17:00:15,001 asyncio      DEBUG    Using selector: EpollSelector
2021-02-02 17:00:15,799 django.utils.autoreload INFO     Watching for file changes with StatReloader
2021-02-02 17:00:42,719 django.utils.autoreload INFO     /code/sample/views.py changed, reloading.
2021-02-02 17:00:42,719 asyncio      DEBUG    Using selector: EpollSelector
2021-02-02 17:00:43,130 django.utils.autoreload INFO     Watching for file changes with StatReloader
2021-02-02 17:02:28,993 django.request WARNING  Not Found: /favicon.ico
2021-02-02 17:02:35,022 django.request ERROR    Internal Server Error: /login
Traceback (most recent call last):
  File "/usr/local/lib/python3.9/site-packages/django/db/backends/utils.py", line 84, in _execute
    return self.cursor.execute(sql, params)
psycopg2.errors.UndefinedTable: relation "auth_user" does not exist
LINE 1: ...user"."is_active", "auth_user"."date_joined" FROM "auth_user...
                                                             ^


The above exception was the direct cause of the following exception:

Traceback (most recent call last):
  File "/usr/local/lib/python3.9/site-packages/django/core/handlers/exception.py", line 47, in inner
    response = get_response(request)
  File "/usr/local/lib/python3.9/site-packages/django/core/handlers/base.py", line 181, in _get_response
    response = wrapped_callback(request, *callback_args, **callback_kwargs)
  File "/code/sample/decorators.py", line 9, in wrapper_func
    return view_func(request, *args, **kwargs)
  File "/code/sample/views.py", line 51, in loginPage
    user = authenticate(request, username=username, password=password)
  File "/usr/local/lib/python3.9/site-packages/django/contrib/auth/__init__.py", line 73, in authenticate
    user = backend.authenticate(request, **credentials)
  File "/usr/local/lib/python3.9/site-packages/django/contrib/auth/backends.py", line 42, in authenticate
    user = UserModel._default_manager.get_by_natural_key(username)
  File "/usr/local/lib/python3.9/site-packages/django/contrib/auth/base_user.py", line 45, in get_by_natural_key
    return self.get(**{self.model.USERNAME_FIELD: username})
  File "/usr/local/lib/python3.9/site-packages/django/db/models/manager.py", line 85, in manager_method
    return getattr(self.get_queryset(), name)(*args, **kwargs)
  File "/usr/local/lib/python3.9/site-packages/django/db/models/query.py", line 425, in get
    num = len(clone)
  File "/usr/local/lib/python3.9/site-packages/django/db/models/query.py", line 269, in __len__
    self._fetch_all()
  File "/usr/local/lib/python3.9/site-packages/django/db/models/query.py", line 1308, in _fetch_all
    self._result_cache = list(self._iterable_class(self))
  File "/usr/local/lib/python3.9/site-packages/django/db/models/query.py", line 53, in __iter__
    results = compiler.execute_sql(chunked_fetch=self.chunked_fetch, chunk_size=self.chunk_size)
  File "/usr/local/lib/python3.9/site-packages/django/db/models/sql/compiler.py", line 1156, in execute_sql
    cursor.execute(sql, params)
  File "/usr/local/lib/python3.9/site-packages/django/db/backends/utils.py", line 98, in execute
    return super().execute(sql, params)
  File "/usr/local/lib/python3.9/site-packages/django/db/backends/utils.py", line 66, in execute
    return self._execute_with_wrappers(sql, params, many=False, executor=self._execute)
  File "/usr/local/lib/python3.9/site-packages/django/db/backends/utils.py", line 75, in _execute_with_wrappers
    return executor(sql, params, many, context)
  File "/usr/local/lib/python3.9/site-packages/django/db/backends/utils.py", line 84, in _execute
    return self.cursor.execute(sql, params)
  File "/usr/local/lib/python3.9/site-packages/django/db/utils.py", line 90, in __exit__
    raise dj_exc_value.with_traceback(traceback) from exc_value
  File "/usr/local/lib/python3.9/site-packages/django/db/backends/utils.py", line 84, in _execute
    return self.cursor.execute(sql, params)
django.db.utils.ProgrammingError: relation "auth_user" does not exist
LINE 1: ...user"."is_active", "auth_user"."date_joined" FROM "auth_user...
                                                             ^

2021-02-02 17:03:45,900 django.security.csrf WARNING  Forbidden (CSRF token missing or incorrect.): /
2021-02-02 17:04:02,729 django.request WARNING  Not Found: /pdf/
2021-02-02 17:04:24,457 django.request ERROR    Internal Server Error: /pdf
Traceback (most recent call last):
  File "/usr/local/lib/python3.9/site-packages/django/core/handlers/exception.py", line 47, in inner
    response = get_response(request)
  File "/usr/local/lib/python3.9/site-packages/django/core/handlers/base.py", line 181, in _get_response
    response = wrapped_callback(request, *callback_args, **callback_kwargs)
  File "/code/sample/decorators.py", line 9, in wrapper_func
    return view_func(request, *args, **kwargs)
  File "/code/sample/views.py", line 78, in generatePDF
    p = drawTestReport(buffer)
  File "/code/sample/decorators.py", line 6, in wrapper_func
    if request.user.is_authenticated:
AttributeError: '_io.BytesIO' object has no attribute 'user'
2021-02-02 17:05:01,232 django.utils.autoreload INFO     /code/sample/views.py changed, reloading.
2021-02-02 17:05:01,232 asyncio      DEBUG    Using selector: EpollSelector
2021-02-02 17:05:01,597 django.utils.autoreload INFO     Watching for file changes with StatReloader
2021-02-02 17:06:28,917 django.request ERROR    Internal Server Error: /csv
Traceback (most recent call last):
  File "/usr/local/lib/python3.9/site-packages/django/core/handlers/exception.py", line 47, in inner
    response = get_response(request)
  File "/usr/local/lib/python3.9/site-packages/django/core/handlers/base.py", line 188, in _get_response
    self.check_response(response, callback)
  File "/usr/local/lib/python3.9/site-packages/django/core/handlers/base.py", line 309, in check_response
    raise ValueError(
ValueError: The view sample.views.generateCSV didn't return an HttpResponse object. It returned None instead.
2021-02-02 17:09:48,246 django.utils.autoreload INFO     /code/sample/views.py changed, reloading.
2021-02-02 17:09:48,246 asyncio      DEBUG    Using selector: EpollSelector
2021-02-02 17:09:48,856 django.utils.autoreload INFO     Watching for file changes with StatReloader
2021-02-02 17:09:54,245 django.request ERROR    Internal Server Error: /csv
Traceback (most recent call last):
  File "/usr/local/lib/python3.9/site-packages/django/core/handlers/exception.py", line 47, in inner
    response = get_response(request)
  File "/usr/local/lib/python3.9/site-packages/django/core/handlers/base.py", line 181, in _get_response
    response = wrapped_callback(request, *callback_args, **callback_kwargs)
  File "/code/sample/views.py", line 117, in generateCSV
    return HttpResponseNotFound("There is no valid report")
NameError: name 'HttpResponseNotFound' is not defined
2021-02-02 17:10:28,830 django.utils.autoreload INFO     /code/sample/views.py changed, reloading.
2021-02-02 17:10:28,830 asyncio      DEBUG    Using selector: EpollSelector
2021-02-02 17:10:29,204 django.utils.autoreload INFO     Watching for file changes with StatReloader
2021-02-02 17:10:37,153 django.request WARNING  Not Found: /csv
2021-02-02 17:11:12,110 django.security.csrf WARNING  Forbidden (CSRF token missing or incorrect.): /csv
2021-02-02 17:11:21,812 django.request WARNING  Not Found: /csv
2021-02-02 17:22:03,454 django.utils.autoreload INFO     /code/sample/views.py changed, reloading.
2021-02-02 17:22:03,454 asyncio      DEBUG    Using selector: EpollSelector
2021-02-02 17:22:03,837 django.utils.autoreload INFO     Watching for file changes with StatReloader
2021-02-02 17:22:15,097 django.utils.autoreload INFO     /code/sample/views.py changed, reloading.
2021-02-02 17:22:15,098 asyncio      DEBUG    Using selector: EpollSelector
2021-02-02 17:22:15,465 django.utils.autoreload INFO     Watching for file changes with StatReloader
2021-02-02 17:23:05,692 django.utils.autoreload INFO     /code/sample/urls.py changed, reloading.
2021-02-02 17:23:05,693 asyncio      DEBUG    Using selector: EpollSelector
2021-02-02 17:23:06,132 django.utils.autoreload INFO     Watching for file changes with StatReloader
2021-02-02 17:23:15,513 django.utils.autoreload INFO     /code/sample/urls.py changed, reloading.
2021-02-02 17:23:15,514 asyncio      DEBUG    Using selector: EpollSelector
2021-02-02 17:23:15,953 django.utils.autoreload INFO     Watching for file changes with StatReloader
2021-02-02 17:23:58,538 django.request WARNING  Not Found: /generate
